[2022-07-05 18:04:32,680] {taskinstance.py:1159} INFO - Dependencies all met for <TaskInstance: twitter_dag.process_twitter_data manual__2022-07-05T21:04:25.004544+00:00 [queued]>
[2022-07-05 18:04:32,689] {taskinstance.py:1159} INFO - Dependencies all met for <TaskInstance: twitter_dag.process_twitter_data manual__2022-07-05T21:04:25.004544+00:00 [queued]>
[2022-07-05 18:04:32,689] {taskinstance.py:1356} INFO - 
--------------------------------------------------------------------------------
[2022-07-05 18:04:32,689] {taskinstance.py:1357} INFO - Starting attempt 1 of 4
[2022-07-05 18:04:32,689] {taskinstance.py:1358} INFO - 
--------------------------------------------------------------------------------
[2022-07-05 18:04:32,705] {taskinstance.py:1377} INFO - Executing <Task(DatabricksRunNowOperator): process_twitter_data> on 2022-07-05 21:04:25.004544+00:00
[2022-07-05 18:04:32,707] {standard_task_runner.py:52} INFO - Started process 38339 to run task
[2022-07-05 18:04:32,710] {standard_task_runner.py:79} INFO - Running: ['airflow', 'tasks', 'run', 'twitter_dag', 'process_twitter_data', 'manual__2022-07-05T21:04:25.004544+00:00', '--job-id', '32', '--raw', '--subdir', 'DAGS_FOLDER/twitter_dag.py', '--cfg-path', '/tmp/tmpe5d02sfj', '--error-file', '/tmp/tmpz2nugke7']
[2022-07-05 18:04:32,711] {standard_task_runner.py:80} INFO - Job 32: Subtask process_twitter_data
[2022-07-05 18:04:32,751] {task_command.py:370} INFO - Running <TaskInstance: twitter_dag.process_twitter_data manual__2022-07-05T21:04:25.004544+00:00 [running]> on host nicholas-VirtualBox
[2022-07-05 18:04:32,819] {taskinstance.py:1569} INFO - Exporting the following env vars:
AIRFLOW_CTX_DAG_EMAIL=nicholas.comuni@outlook.com
AIRFLOW_CTX_DAG_OWNER=Nicholas
AIRFLOW_CTX_DAG_ID=twitter_dag
AIRFLOW_CTX_TASK_ID=process_twitter_data
AIRFLOW_CTX_EXECUTION_DATE=2022-07-05T21:04:25.004544+00:00
AIRFLOW_CTX_TRY_NUMBER=1
AIRFLOW_CTX_DAG_RUN_ID=manual__2022-07-05T21:04:25.004544+00:00
[2022-07-05 18:04:32,825] {base.py:68} INFO - Using connection ID 'databricks_conn' for task execution.
[2022-07-05 18:04:32,827] {databricks_base.py:406} INFO - Using token auth. For security reasons, please set token in Password field instead of extra
[2022-07-05 18:04:33,809] {taskinstance.py:1889} ERROR - Task failed with exception
Traceback (most recent call last):
  File "/home/nicholas/.local/lib/python3.10/site-packages/airflow/providers/databricks/hooks/databricks_base.py", line 498, in _do_api_call
    for attempt in self._get_retry_object():
  File "/home/nicholas/.local/lib/python3.10/site-packages/tenacity/__init__.py", line 382, in __iter__
    do = self.iter(retry_state=retry_state)
  File "/home/nicholas/.local/lib/python3.10/site-packages/tenacity/__init__.py", line 349, in iter
    return fut.result()
  File "/usr/lib/python3.10/concurrent/futures/_base.py", line 439, in result
    return self.__get_result()
  File "/usr/lib/python3.10/concurrent/futures/_base.py", line 391, in __get_result
    raise self._exception
  File "/home/nicholas/.local/lib/python3.10/site-packages/airflow/providers/databricks/hooks/databricks_base.py", line 508, in _do_api_call
    response.raise_for_status()
  File "/home/nicholas/.local/lib/python3.10/site-packages/requests/models.py", line 1021, in raise_for_status
    raise HTTPError(http_error_msg, response=self)
requests.exceptions.HTTPError: 400 Client Error: Bad Request for url: https://adb-770153189229877.17.azuredatabricks.net/api/2.1/jobs/run-now

During handling of the above exception, another exception occurred:

Traceback (most recent call last):
  File "/home/nicholas/.local/lib/python3.10/site-packages/airflow/providers/databricks/operators/databricks.py", line 654, in execute
    self.run_id = hook.run_now(self.json)
  File "/home/nicholas/.local/lib/python3.10/site-packages/airflow/providers/databricks/hooks/databricks.py", line 138, in run_now
    response = self._do_api_call(RUN_NOW_ENDPOINT, json)
  File "/home/nicholas/.local/lib/python3.10/site-packages/airflow/providers/databricks/hooks/databricks_base.py", line 514, in _do_api_call
    raise AirflowException(
airflow.exceptions.AirflowException: Response: b'{"error_code":"INVALID_PARAMETER_VALUE","message":"Job 0 does not exist."}', Status Code: 400
[2022-07-05 18:04:33,820] {taskinstance.py:1395} INFO - Marking task as UP_FOR_RETRY. dag_id=twitter_dag, task_id=process_twitter_data, execution_date=20220705T210425, start_date=20220705T210432, end_date=20220705T210433
[2022-07-05 18:04:33,832] {standard_task_runner.py:92} ERROR - Failed to execute job 32 for task process_twitter_data (Response: b'{"error_code":"INVALID_PARAMETER_VALUE","message":"Job 0 does not exist."}', Status Code: 400; 38339)
[2022-07-05 18:04:33,842] {local_task_job.py:156} INFO - Task exited with return code 1
[2022-07-05 18:04:33,861] {local_task_job.py:273} INFO - 0 downstream tasks scheduled from follow-on schedule check
